<?xml version="1.0" ?>
<robot name="LINE" xmlns:xacro="http://www.ros.org/wiki/xacro">

<xacro:include filename="$(find LINE_description)/urdf/materials.xacro" />
<xacro:include filename="$(find LINE_description)/urdf/LINE.trans" />
<xacro:include filename="$(find LINE_description)/urdf/LINE.gazebo" />
<link name="base_link">
  <inertial>
    <origin xyz="-0.003423563684368489 -0.0176715199304114 -0.00939646321167365" rpy="0 0 0"/>
    <mass value="2.063351837070663"/>
    <inertia ixx="0.002087" iyy="0.007887" izz="0.009536" ixy="-0.000205" iyz="-5.2e-05" ixz="-0.000348"/>
  </inertial>
  <visual>
    <origin xyz="0 0 0" rpy="0 0 0"/>
    <geometry>
      <mesh filename="package://LINE_description/meshes/base_link.stl" scale="0.001 0.001 0.001"/>
    </geometry>
    <material name="silver"/>
  </visual>
  <collision>
    <origin xyz="0 0 0" rpy="0 0 0"/>
    <geometry>
      <mesh filename="package://LINE_description/meshes/base_link.stl" scale="0.001 0.001 0.001"/>
    </geometry>
  </collision>
</link>

<link name="wheel_2_1">
  <inertial>
    <origin xyz="-4.946127957761171e-07 -0.003499729902988011 -4.522608891832647e-07" rpy="0 0 0"/>
    <mass value="0.10789407269672445"/>
    <inertia ixx="1.7e-05" iyy="3.4e-05" izz="1.7e-05" ixy="0.0" iyz="0.0" ixz="0.0"/>
  </inertial>
  <visual>
    <origin xyz="0.071603 0.071039 0.031511" rpy="0 0 0"/>
    <geometry>
      <mesh filename="package://LINE_description/meshes/wheel_2_1.stl" scale="0.001 0.001 0.001"/>
    </geometry>
    <material name="silver"/>
  </visual>
  <collision>
    <origin xyz="0.071603 0.071039 0.031511" rpy="0 0 0"/>
    <geometry>
      <mesh filename="package://LINE_description/meshes/wheel_2_1.stl" scale="0.001 0.001 0.001"/>
    </geometry>
  </collision>
</link>

<link name="wheel_1_1">
  <inertial>
    <origin xyz="-4.946127936528155e-07 0.0035002700970102676 -4.5226088830896405e-07" rpy="0 0 0"/>
    <mass value="0.10789407269672448"/>
    <inertia ixx="1.7e-05" iyy="3.4e-05" izz="1.7e-05" ixy="0.0" iyz="0.0" ixz="0.0"/>
  </inertial>
  <visual>
    <origin xyz="0.076603 -0.038961 0.031761" rpy="0 0 0"/>
    <geometry>
      <mesh filename="package://LINE_description/meshes/wheel_1_1.stl" scale="0.001 0.001 0.001"/>
    </geometry>
    <material name="silver"/>
  </visual>
  <collision>
    <origin xyz="0.076603 -0.038961 0.031761" rpy="0 0 0"/>
    <geometry>
      <mesh filename="package://LINE_description/meshes/wheel_1_1.stl" scale="0.001 0.001 0.001"/>
    </geometry>
  </collision>
</link>

<joint name="Rev1" type="continuous">
  <origin xyz="-0.071603 -0.071039 -0.031511" rpy="0 0 0"/>
  <parent link="base_link"/>
  <child link="wheel_2_1"/>
  <axis xyz="-0.0 -1.0 -0.0"/>
</joint>

<joint name="Rev2" type="continuous">
  <origin xyz="-0.076603 0.038961 -0.031761" rpy="0 0 0"/>
  <parent link="base_link"/>
  <child link="wheel_1_1"/>
  <axis xyz="0.0 1.0 0.0"/>
</joint>

</robot>
